// 1. Error handling inside the async function
const fetchUsers = async () => {
  try {
    const response = await fetch('https://jsonplaceholder.typicode.com/users');
    const users = await response.json();
    console.log(users);
  } catch (error) {
    console.log(error.message);
  }
};

fetchUsers();

// 2. Error handling outside the async function

// const fetchUsers = async () => {
//   const response = await fetch('https://jsonplaceholder.typicode.com/users');
//   const users = await response.json();
//   return users;
// };

// fetchUsers()
//   .then(users => console.log(users))
//   .catch(error => console.log(error));

// const fetchUsers = async () => {
//   const response = await fetch('https://jsonplaceholder.typicode.com/users');
//   const users = await response.json();
//   return users;
// };

// const doStuff = async () => {
//   try {
//     const users = await fetchUsers();
//     console.log(users);
//   } catch (error) {
//     console.log(error.message);
//   }
// };

// doStuff();
